/root/anaconda3/envs/dl/lib/python3.6/runpy.py:125: RuntimeWarning: 'ipdb.__main__' found in sys.modules after import of package 'ipdb', but prior to execution of 'ipdb.__main__'; this may result in unpredictable behaviour
  warn(RuntimeWarning(msg))
> [0;32m/workhere/vtt_challenge_2019/code/cli.py[0m(1)[0;36m<module>[0;34m()[0m
[0;32m----> 1 [0;31m[0;32mfrom[0m [0mpathlib[0m [0;32mimport[0m [0mPath[0m[0;34m[0m[0;34m[0m[0m
[0m[0;32m      2 [0;31m[0;32mimport[0m [0mrandom[0m[0;34m[0m[0;34m[0m[0m
[0m[0;32m      3 [0;31m[0;34m[0m[0m
[0m
ipdb> Traceback (most recent call last):
  File "/root/anaconda3/envs/dl/lib/python3.6/site-packages/ipdb/__main__.py", line 168, in main
    pdb._runscript(mainpyfile)
  File "/root/anaconda3/envs/dl/lib/python3.6/pdb.py", line 1548, in _runscript
    self.run(statement)
  File "/root/anaconda3/envs/dl/lib/python3.6/bdb.py", line 434, in run
    exec(cmd, globals, locals)
  File "<string>", line 1, in <module>
  File "/workhere/vtt_challenge_2019/code/cli.py", line 1, in <module>
    from pathlib import Path
  File "/workhere/vtt_challenge_2019/code/cli.py", line 1, in <module>
    from pathlib import Path
  File "/root/anaconda3/envs/dl/lib/python3.6/bdb.py", line 51, in trace_dispatch
    return self.dispatch_line(frame)
  File "/root/anaconda3/envs/dl/lib/python3.6/bdb.py", line 69, in dispatch_line
    self.user_line(frame)
  File "/root/anaconda3/envs/dl/lib/python3.6/pdb.py", line 261, in user_line
    self.interaction(frame, None)
  File "/root/anaconda3/envs/dl/lib/python3.6/site-packages/IPython/core/debugger.py", line 297, in interaction
    OldPdb.interaction(self, frame, traceback)
  File "/root/anaconda3/envs/dl/lib/python3.6/pdb.py", line 352, in interaction
    self._cmdloop()
  File "/root/anaconda3/envs/dl/lib/python3.6/pdb.py", line 321, in _cmdloop
    self.cmdloop()
  File "/root/anaconda3/envs/dl/lib/python3.6/cmd.py", line 126, in cmdloop
    line = input(self.prompt)
OSError: [Errno 9] Bad file descriptor
Uncaught exception. Entering post mortem debugging
Running 'cont' or 'step' will restart the program
> [0;32m/root/anaconda3/envs/dl/lib/python3.6/cmd.py[0m(126)[0;36mcmdloop[0;34m()[0m
[0;32m    125 [0;31m                        [0;32mtry[0m[0;34m:[0m[0;34m[0m[0;34m[0m[0m
[0m[0;32m--> 126 [0;31m                            [0mline[0m [0;34m=[0m [0minput[0m[0;34m([0m[0mself[0m[0;34m.[0m[0mprompt[0m[0;34m)[0m[0;34m[0m[0;34m[0m[0m
[0m[0;32m    127 [0;31m                        [0;32mexcept[0m [0mEOFError[0m[0;34m:[0m[0;34m[0m[0;34m[0m[0m
[0m
ipdb> Traceback (most recent call last):
  File "/root/anaconda3/envs/dl/lib/python3.6/site-packages/ipdb/__main__.py", line 168, in main
    pdb._runscript(mainpyfile)
  File "/root/anaconda3/envs/dl/lib/python3.6/pdb.py", line 1548, in _runscript
    self.run(statement)
  File "/root/anaconda3/envs/dl/lib/python3.6/bdb.py", line 434, in run
    exec(cmd, globals, locals)
  File "<string>", line 1, in <module>
  File "/workhere/vtt_challenge_2019/code/cli.py", line 1, in <module>
    from pathlib import Path
  File "/workhere/vtt_challenge_2019/code/cli.py", line 1, in <module>
    from pathlib import Path
  File "/root/anaconda3/envs/dl/lib/python3.6/bdb.py", line 51, in trace_dispatch
    return self.dispatch_line(frame)
  File "/root/anaconda3/envs/dl/lib/python3.6/bdb.py", line 69, in dispatch_line
    self.user_line(frame)
  File "/root/anaconda3/envs/dl/lib/python3.6/pdb.py", line 261, in user_line
    self.interaction(frame, None)
  File "/root/anaconda3/envs/dl/lib/python3.6/site-packages/IPython/core/debugger.py", line 297, in interaction
    OldPdb.interaction(self, frame, traceback)
  File "/root/anaconda3/envs/dl/lib/python3.6/pdb.py", line 352, in interaction
    self._cmdloop()
  File "/root/anaconda3/envs/dl/lib/python3.6/pdb.py", line 321, in _cmdloop
    self.cmdloop()
  File "/root/anaconda3/envs/dl/lib/python3.6/cmd.py", line 126, in cmdloop
    line = input(self.prompt)
OSError: [Errno 9] Bad file descriptor

During handling of the above exception, another exception occurred:

Traceback (most recent call last):
  File "/root/anaconda3/envs/dl/lib/python3.6/runpy.py", line 193, in _run_module_as_main
    "__main__", mod_spec)
  File "/root/anaconda3/envs/dl/lib/python3.6/runpy.py", line 85, in _run_code
    exec(code, run_globals)
  File "/root/anaconda3/envs/dl/lib/python3.6/site-packages/ipdb/__main__.py", line 189, in <module>
    main()
  File "/root/anaconda3/envs/dl/lib/python3.6/site-packages/ipdb/__main__.py", line 184, in main
    pdb.interaction(None, t)
  File "/root/anaconda3/envs/dl/lib/python3.6/site-packages/IPython/core/debugger.py", line 297, in interaction
    OldPdb.interaction(self, frame, traceback)
  File "/root/anaconda3/envs/dl/lib/python3.6/pdb.py", line 352, in interaction
    self._cmdloop()
  File "/root/anaconda3/envs/dl/lib/python3.6/pdb.py", line 321, in _cmdloop
    self.cmdloop()
  File "/root/anaconda3/envs/dl/lib/python3.6/cmd.py", line 126, in cmdloop
    line = input(self.prompt)
OSError: [Errno 9] Bad file descriptor

If you suspect this is an IPython bug, please report it at:
    https://github.com/ipython/ipython/issues
or send an email to the mailing list at ipython-dev@python.org

You can print a more detailed traceback right now with "%tb", or use "%debug"
to interactively debug it.

Extra-detailed tracebacks for bug-reporting purposes can be enabled via:
    %config Application.verbose_crash=True

